Workbook
Name Année: VentesMagasins!$M$2:$M$1001
Name CA: VentesMagasins!$R$2:$R$1001
Name CA_retour: VentesMagasins!$S$2:$S$1001
Name Categorie: VentesMagasins!$F$2:$F$1001
Name Categorie_nett: VentesMagasins!$O$2:$O$1001
Name Clée: VentesMagasins!$M$1:$M$1001
Name ClientID: Clients!$A$2:$A$301
Name ClientID: VentesMagasins!$B$2:$B$1001
Name ClientID1: Tbl_Clients[ClientID1]
Name DateVente: VentesMagasins!$C$2:$C$1001
Name Magasin: VentesMagasins!$D$2:$D$1001
Name Mois: VentesMagasins!$N$2:$N$1001
Name Moyenne_client: VentesMagasins!$V$2:$V$1001
Name NoteClient: VentesMagasins!$L$2:$L$1001
Name NoteClient_nett1: VentesMagasins!$U$2:$U$1001
Name NoteClient_Nette: VentesMagasins!$T$2:$T$1001
Name OrderID: VentesMagasins!$A$2:$A$1001
Name PrixUnitaire: VentesMagasins!$H$2:$H$1001
Name Produit: VentesMagasins!$E$2:$E$1001
Name Quantité: VentesMagasins!$G$2:$G$1001
Name Region: VentesMagasins!$W$2:$W$1001
Name Région: Clients!$B$2:$B$301
Name Remise: VentesMagasins!$I$2:$I$1001
Name Remise_nett: VentesMagasins!$P$2:$P$1001
Name Retour: VentesMagasins!$K$2:$K$1001
Name Total: VentesMagasins!$J$2:$J$1001
Name Total_Nett: VentesMagasins!$Q$2:$Q$1001
Name Type_Client: VentesMagasins!$X$2:$X$1001
Name TypeClient: Clients!$C$2:$C$301

Sheet VentesMagasins
A1: OrderID | B1: ClientID | C1: DateVente | D1: Magasin | E1: Produit | F1: Categorie | G1: Quantité | H1: PrixUnitaire | I1: Remise | J1: Total | K1: Retour | L1: NoteClient | M1: Année | N1: Mois | O1: Categorie_nett | P1: Remise_nett | Q1: Total_Nett | R1: CA | S1: CA_retour | T1: NoteClient_Nette | U1: NoteClient_nett1 | V1: Moyenne_client | W1: Region | X1: Type_Client | Y1: Mois_
A2: 1 | B2: C1291 | C2: 45686 | D2: M5 | E2: Chaise | F2: Électronique | G2: 2 | H2: 130 | I2: 0.15 | J2: 221.0 | K2: 0 | L2: 5.0 | M2: =YEAR(VentesMagasins!$C2) -> 2025 | N2: {=MONTH(DateVente)} -> #VALUE! | O2: =PROPER(VentesMagasins!$F2) -> Électronique | P2: =VALUE(CLEAN(TRIM(SUBSTITUTE(VentesMagasins!$I2,".",",")))) -> 0.15 | Q2: =VALUE(TRIM(SUBSTITUTE(VentesMagasins!$J2,".",","))) -> 221 | R2: =Q2*(1-P2) -> 187.85 | S2: =IF(VentesMagasins!$K2=1,(-1)*R2,R2) -> 187.85 | T2: =IFERROR(VALUE(TRIM(SUBSTITUTE(VentesMagasins!$L2,".",","))),0) -> 5 | U2: =ROUND(IF(T2=0,AVERAGE(T2:T1001),T2),0) -> 5 | V2: =IF(AND(U2>0,U2<=2),"faible",IF(AND(U2>=3,U2<=4),"moyenne",IF(U2=5,"élévé",0))) -> élévé | W2: =_xlfn.XLOOKUP(VentesMagasins!$B2,Clients!ClientID,Région) -> Est | X2: =INDEX(TypeClient,MATCH(VentesMagasins!$B2,Clients!ClientID)) -> Fidèle | Y2: {=TEXT(DateVente,"mmm")} -> janv
A3: 2 | B3: C1241 | C3: 45234 | D3: M2 | E3: Plante | F3: Décoration | G3: 1 | H3: 70 | I3: 0.15 | J3: 59.5 | K3: 0 | L3: 4.0 | M3: =YEAR(VentesMagasins!$C3) -> 2023 | N3: {=MONTH(DateVente)} -> #VALUE! | O3: =PROPER(VentesMagasins!$F3) -> Décoration | P3: =VALUE(CLEAN(TRIM(SUBSTITUTE(VentesMagasins!$I3,".",",")))) -> 0.15 | Q3: =VALUE(TRIM(SUBSTITUTE(VentesMagasins!$J3,".",","))) -> 59.5 | R3: =Q3*(1-P3) -> 50.575 | S3: =IF(VentesMagasins!$K3=1,(-1)*R3,R3) -> 50.575 | T3: =IFERROR(VALUE(TRIM(SUBSTITUTE(VentesMagasins!$L3,".",","))),0) -> 4 | U3: =ROUND(IF(T3=0,AVERAGE(T3:T1002),T3),0) -> 4 | V3: =IF(AND(U3>0,U3<=2),"faible",IF(AND(U3>=3,U3<=4),"moyenne",IF(U3=5,"élévé",0))) -> moyenne | W3: =_xlfn.XLOOKUP(VentesMagasins!$B3,Clients!ClientID,Région) -> Centre | X3: =INDEX(TypeClient,MATCH(VentesMagasins!$B3,Clients!ClientID)) -> Occasionnel | Y3: nov
A4: 3 | B4: C1222 | C4: 45482 | D4: M1 | E4: Enceinte | F4: Décoration | G4: 4 | H4: 93 | I4: 0.0 | J4: 372.0 | K4: 1 | L4: 3.0 | M4: =YEAR(VentesMagasins!$C4) -> 2024 | N4: {=MONTH(DateVente)} -> #VALUE! | O4: =PROPER(VentesMagasins!$F4) -> Décoration | P4: =VALUE(CLEAN(TRIM(SUBSTITUTE(VentesMagasins!$I4,".",",")))) -> 0 | Q4: =VALUE(TRIM(SUBSTITUTE(VentesMagasins!$J4,".",","))) -> 372 | R4: =Q4*(1-P4) -> 372 | S4: =IF(VentesMagasins!$K4=1,(-1)*R4,R4) -> -372 | T4: =IFERROR(VALUE(TRIM(SUBSTITUTE(VentesMagasins!$L4,".",","))),0) -> 3 | U4: =ROUND(IF(T4=0,AVERAGE(T4:T1003),T4),0) -> 3 | V4: =IF(AND(U4>0,U4<=2),"faible",IF(AND(U4>=3,U4<=4),"moyenne",IF(U4=5,"élévé",0))) -> moyenne | W4: =_xlfn.XLOOKUP(VentesMagasins!$B4,Clients!ClientID,Région) -> Est | X4: =INDEX(TypeClient,MATCH(VentesMagasins!$B4,Clients!ClientID)) -> Fidèle | Y4: juil
A5: 4 | B5: C1057 | C5: 45062 | D5: M3 | E5: Lampe | F5: Décoration | G5: 1 | H5: 114 | I5: 0.15 | J5: 96.89999999999999 | K5: 0 | L5: 4.0 | M5: =YEAR(VentesMagasins!$C5) -> 2023 | N5: {=MONTH(DateVente)} -> #VALUE! | O5: =PROPER(VentesMagasins!$F5) -> Décoration | P5: =VALUE(CLEAN(TRIM(SUBSTITUTE(VentesMagasins!$I5,".",",")))) -> 0.15 | Q5: =VALUE(TRIM(SUBSTITUTE(VentesMagasins!$J5,".",","))) -> 96.9 | R5: =Q5*(1-P5) -> 82.365 | S5: =IF(VentesMagasins!$K5=1,(-1)*R5,R5) -> 82.365 | T5: =IFERROR(VALUE(TRIM(SUBSTITUTE(VentesMagasins!$L5,".",","))),0) -> 4 | U5: =ROUND(IF(T5=0,AVERAGE(T5:T1004),T5),0) -> 4 | V5: =IF(AND(U5>0,U5<=2),"faible",IF(AND(U5>=3,U5<=4),"moyenne",IF(U5=5,"élévé",0))) -> moyenne | W5: =_xlfn.XLOOKUP(VentesMagasins!$B5,Clients!ClientID,Région) -> Nord | X5: =INDEX(TypeClient,MATCH(VentesMagasins!$B5,Clients!ClientID)) -> Occasionnel | Y5: mai
A6: 5 | B6: C1058 | C6: 45414 | D6: M1 | E6: Enceinte | F6: Meuble | G6: 4 | H6: 38 | I6: 0.05 | J6: 144.4 | K6: 0 | L6: 2.0 | M6: =YEAR(VentesMagasins!$C6) -> 2024 | N6: {=MONTH(DateVente)} -> #VALUE! | O6: =PROPER(VentesMagasins!$F6) -> Meuble | P6: =VALUE(CLEAN(TRIM(SUBSTITUTE(VentesMagasins!$I6,".",",")))) -> 0.05 | Q6: =VALUE(TRIM(SUBSTITUTE(VentesMagasins!$J6,".",","))) -> 144.4 | R6: =Q6*(1-P6) -> 137.18 | S6: =IF(VentesMagasins!$K6=1,(-1)*R6,R6) -> 137.18 | T6: =IFERROR(VALUE(TRIM(SUBSTITUTE(VentesMagasins!$L6,".",","))),0) -> 2 | U6: =ROUND(IF(T6=0,AVERAGE(T6:T1005),T6),0) -> 2 | V6: =IF(AND(U6>0,U6<=2),"faible",IF(AND(U6>=3,U6<=4),"moyenne",IF(U6=5,"élévé",0))) -> faible | W6: =_xlfn.XLOOKUP(VentesMagasins!$B6,Clients!ClientID,Région) -> Centre | X6: =INDEX(TypeClient,MATCH(VentesMagasins!$B6,Clients!ClientID)) -> Nouveau | Y6: mai
A7: 6 | B7: C1138 | C7: 45439 | D7: M2 | E7: Canapé | F7: Décoration | G7: 3 | H7: 234 | I7: 0.05 | J7: 666.9 | K7: 0 | L7: 3.0 | M7: =YEAR(VentesMagasins!$C7) -> 2024 | N7: {=MONTH(DateVente)} -> #VALUE! | O7: =PROPER(VentesMagasins!$F7) -> Décoration | P7: =VALUE(CLEAN(TRIM(SUBSTITUTE(VentesMagasins!$I7,".",",")))) -> 0.05 | Q7: =VALUE(TRIM(SUBSTITUTE(VentesMagasins!$J7,".",","))) -> 666.9 | R7: =Q7*(1-P7) -> 633.555 | S7: =IF(VentesMagasins!$K7=1,(-1)*R7,R7) -> 633.555 | T7: =IFERROR(VALUE(TRIM(SUBSTITUTE(VentesMagasins!$L7,".",","))),0) -> 3 | U7: =ROUND(IF(T7=0,AVERAGE(T7:T1006),T7),0) -> 3 | V7: =IF(AND(U7>0,U7<=2),"faible",IF(AND(U7>=3,U7<=4),"moyenne",IF(U7=5,"élévé",0))) -> moyenne | W7: =_xlfn.XLOOKUP(VentesMagasins!$B7,Clients!ClientID,Région) -> Centre | X7: =INDEX(TypeClient,MATCH(VentesMagasins!$B7,Clients!ClientID)) -> Nouveau | Y7: mai
A8: 7 | B8: C1094 | C8: 45046 | D8: M5 | E8: Lampe | F8: Électronique | G8: 3 | H8: 85 | I8: 0.0 | J8: 255.0 | K8: 0 | L8: 4.0 | M8: =YEAR(VentesMagasins!$C8) -> 2023 | N8: {=MONTH(DateVente)} -> #VALUE! | O8: =PROPER(VentesMagasins!$F8) -> Électronique | P8: =VALUE(CLEAN(TRIM(SUBSTITUTE(VentesMagasins!$I8,".",",")))) -> 0 | Q8: =VALUE(TRIM(SUBSTITUTE(VentesMagasins!$J8,".",","))) -> 255 | R8: =Q8*(1-P8) -> 255 | S8: =IF(VentesMagasins!$K8=1,(-1)*R8,R8) -> 255 | T8: =IFERROR(VALUE(TRIM(SUBSTITUTE(VentesMagasins!$L8,".",","))),0) -> 4 | U8: =ROUND(IF(T8=0,AVERAGE(T8:T1007),T8),0) -> 4 | V8: =IF(AND(U8>0,U8<=2),"faible",IF(AND(U8>=3,U8<=4),"moyenne",IF(U8=5,"élévé",0))) -> moyenne | W8: =_xlfn.XLOOKUP(VentesMagasins!$B8,Clients!ClientID,Région) -> Centre | X8: =INDEX(TypeClient,MATCH(VentesMagasins!$B8,Clients!ClientID)) -> Nouveau | Y8: avr
A9: 8 | B9: C1144 | C9: 45312 | D9: M3 | E9: Télévision | F9: Décoration | G9: 4 | H9: 78 | I9: 0.0 | J9: 312.0 | K9: 0 | L9: 4.0 | M9: =YEAR(VentesMagasins!$C9) -> 2024 | N9: {=MONTH(DateVente)} -> #VALUE! | O9: =PROPER(VentesMagasins!$F9) -> Décoration | P9: =VALUE(CLEAN(TRIM(SUBSTITUTE(VentesMagasins!$I9,".",",")))) -> 0 | Q9: =VALUE(TRIM(SUBSTITUTE(VentesMagasins!$J9,".",","))) -> 312 | R9: =Q9*(1-P9) -> 312 | S9: =IF(VentesMagasins!$K9=1,(-1)*R9,R9) -> 312 | T9: =IFERROR(VALUE(TRIM(SUBSTITUTE(VentesMagasins!$L9,".",","))),0) -> 4 | U9: =ROUND(IF(T9=0,AVERAGE(T9:T1008),T9),0) -> 4 | V9: =IF(AND(U9>0,U9<=2),"faible",IF(AND(U9>=3,U9<=4),"moyenne",IF(U9=5,"élévé",0))) -> moyenne | W9: =_xlfn.XLOOKUP(VentesMagasins!$B9,Clients!ClientID,Région) -> Sud | X9: =INDEX(TypeClient,MATCH(VentesMagasins!$B9,Clients!ClientID)) -> Nouveau | Y9: janv
A10: 9 | B10: C1135 | C10: 45947 | D10: M4 | E10: Canapé | F10: Meuble | G10: 2 | H10: 143 | I10: 0.0 | J10: 286.0 | K10: 0 | M10: =YEAR(VentesMagasins!$C10) -> 2025 | N10: {=MONTH(DateVente)} -> #VALUE! | O10: =PROPER(VentesMagasins!$F10) -> Meuble | P10: =VALUE(CLEAN(TRIM(SUBSTITUTE(VentesMagasins!$I10,".",",")))) -> 0 | Q10: =VALUE(TRIM(SUBSTITUTE(VentesMagasins!$J10,".",","))) -> 286 | R10: =Q10*(1-P10) -> 286 | S10: =IF(VentesMagasins!$K10=1,(-1)*R10,R10) -> 286 | T10: =IFERROR(VALUE(TRIM(SUBSTITUTE(VentesMagasins!$L10,".",","))),0) -> 0 | U10: =ROUND(IF(T10=0,AVERAGE(T10:T1009),T10),0) -> 3 | V10: =IF(AND(U10>0,U10<=2),"faible",IF(AND(U10>=3,U10<=4),"moyenne",IF(U10=5,"élévé",0))) -> moyenne | W10: =_xlfn.XLOOKUP(VentesMagasins!$B10,Clients!ClientID,Région) -> Est | X10: =INDEX(TypeClient,MATCH(VentesMagasins!$B10,Clients!ClientID)) -> Occasionnel | Y10: oct
A11: 10 | B11: C1295 | C11: 45557 | D11: M5 | E11: Lampe | F11: Décoration | G11: 1 | H11: 363 | I11: 0.0 | J11: 363.0 | K11: 0 | L11: 3.0 | M11: =YEAR(VentesMagasins!$C11) -> 2024 | N11: {=MONTH(DateVente)} -> #VALUE! | O11: =PROPER(VentesMagasins!$F11) -> Décoration | P11: =VALUE(CLEAN(TRIM(SUBSTITUTE(VentesMagasins!$I11,".",",")))) -> 0 | Q11: =VALUE(TRIM(SUBSTITUTE(VentesMagasins!$J11,".",","))) -> 363 | R11: =Q11*(1-P11) -> 363 | S11: =IF(VentesMagasins!$K11=1,(-1)*R11,R11) -> 363 | T11: =IFERROR(VALUE(TRIM(SUBSTITUTE(VentesMagasins!$L11,".",","))),0) -> 3 | U11: =ROUND(IF(T11=0,AVERAGE(T11:T1010),T11),0) -> 3 | V11: =IF(AND(U11>0,U11<=2),"faible",IF(AND(U11>=3,U11<=4),"moyenne",IF(U11=5,"élévé",0))) -> moyenne | W11: =_xlfn.XLOOKUP(VentesMagasins!$B11,Clients!ClientID,Région) -> Sud | X11: =INDEX(TypeClient,MATCH(VentesMagasins!$B11,Clients!ClientID)) -> Nouveau | Y11: sept
A12: 11 | B12: C1059 | C12: 45257 | D12: M2 | E12: Chaise | F12: Meuble | G12: 3 | H12: 278 | I12: 0.05 | J12: 792.3 | K12: 1 | L12: 4.0 | M12: =YEAR(VentesMagasins!$C12) -> 2023 | N12: {=MONTH(DateVente)} -> #VALUE! | O12: =PROPER(VentesMagasins!$F12) -> Meuble | P12: =VALUE(CLEAN(TRIM(SUBSTITUTE(VentesMagasins!$I12,".",",")))) -> 0.05 | Q12: =VALUE(TRIM(SUBSTITUTE(VentesMagasins!$J12,".",","))) -> 792.3 | R12: =Q12*(1-P12) -> 752.685 | S12: =IF(VentesMagasins!$K12=1,(-1)*R12,R12) -> -752.685 | T12: =IFERROR(VALUE(TRIM(SUBSTITUTE(VentesMagasins!$L12,".",","))),0) -> 4 | U12: =ROUND(IF(T12=0,AVERAGE(T12:T1011),T12),0) -> 4 | V12: =IF(AND(U12>0,U12<=2),"faible",IF(AND(U12>=3,U12<=4),"moyenne",IF(U12=5,"élévé",0))) -> moyenne | W12: =_xlfn.XLOOKUP(VentesMagasins!$B12,Clients!ClientID,Région) -> Ouest | X12: =INDEX(TypeClient,MATCH(VentesMagasins!$B12,Clients!ClientID)) -> Nouveau | Y12: nov
A13: 12 | B13: C1003 | C13: 45501 | D13: M2 | E13: Plante | F13: Électronique | G13: 5 | H13: 73 | I13: 0.1 | J13: 328.5 | K13: 1 | L13: 2.0 | M13: =YEAR(VentesMagasins!$C13) -> 2024 | N13: {=MONTH(DateVente)} -> #VALUE! | O13: =PROPER(VentesMagasins!$F13) -> Électronique | P13: =VALUE(CLEAN(TRIM(SUBSTITUTE(VentesMagasins!$I13,".",",")))) -> 0.1 | Q13: =VALUE(TRIM(SUBSTITUTE(VentesMagasins!$J13,".",","))) -> 328.5 | R13: =Q13*(1-P13) -> 295.65 | S13: =IF(VentesMagasins!$K13=1,(-1)*R13,R13) -> -295.65 | T13: =IFERROR(VALUE(TRIM(SUBSTITUTE(VentesMagasins!$L13,".",","))),0) -> 2 | U13: =ROUND(IF(T13=0,AVERAGE(T13:T1012),T13),0) -> 2 | V13: =IF(AND(U13>0,U13<=2),"faible",IF(AND(U13>=3,U13<=4),"moyenne",IF(U13=5,"élévé",0))) -> faible | W13: =_xlfn.XLOOKUP(VentesMagasins!$B13,Clients!ClientID,Région) -> Centre | X13: =INDEX(TypeClient,MATCH(VentesMagasins!$B13,Clients!ClientID)) -> Fidèle | Y13: juil
A14: 13 | B14: C1049 | C14: 45819 | D14: M1 | E14: Plante | F14: Décoration | G14: 3 | H14: 294 | I14: 0.15 | J14: 749.6999999999999 | K14: 0 | L14: 5.0 | M14: =YEAR(VentesMagasins!$C14) -> 2025 | N14: {=MONTH(DateVente)} -> #VALUE! | O14: =PROPER(VentesMagasins!$F14) -> Décoration | P14: =VALUE(CLEAN(TRIM(SUBSTITUTE(VentesMagasins!$I14,".",",")))) -> 0.15 | Q14: =VALUE(TRIM(SUBSTITUTE(VentesMagasins!$J14,".",","))) -> 749.7 | R14: =Q14*(1-P14) -> 637.245 | S14: =IF(VentesMagasins!$K14=1,(-1)*R14,R14) -> 637.245 | T14: =IFERROR(VALUE(TRIM(SUBSTITUTE(VentesMagasins!$L14,".",","))),0) -> 5 | U14: =ROUND(IF(T14=0,AVERAGE(T14:T1013),T14),0) -> 5 | V14: =IF(AND(U14>0,U14<=2),"faible",IF(AND(U14>=3,U14<=4),"moyenne",IF(U14=5,"élévé",0))) -> élévé | W14: =_xlfn.XLOOKUP(VentesMagasins!$B14,Clients!ClientID,Région) -> Centre | X14: =INDEX(TypeClient,MATCH(VentesMagasins!$B14,Clients!ClientID)) -> Fidèle | Y14: juin
A15: 14 | B15: C1150 | C15: 45343 | D15: M3 | E15: Chaise | F15: électronique | G15: 1 | H15: 171 | I15: 0.1 | J15: 153.9 | K15: 0 | M15: =YEAR(VentesMagasins!$C15) -> 2024 | N15: {=MONTH(DateVente)} -> #VALUE! | O15: =PROPER(VentesMagasins!$F15) -> Électronique | P15: =VALUE(CLEAN(TRIM(SUBSTITUTE(VentesMagasins!$I15,".",",")))) -> 0.1 | Q15: =VALUE(TRIM(SUBSTITUTE(VentesMagasins!$J15,".",","))) -> 153.9 | R15: =Q15*(1-P15) -> 138.51 | S15: =IF(VentesMagasins!$K15=1,(-1)*R15,R15) -> 138.51 | T15: =IFERROR(VALUE(TRIM(SUBSTITUTE(VentesMagasins!$L15,".",","))),0) -> 0 | U15: =ROUND(IF(T15=0,AVERAGE(T15:T1014),T15),0) -> 3 | V15: =IF(AND(U15>0,U15<=2),"faible",IF(AND(U15>=3,U15<=4),"moyenne",IF(U15=5,"élévé",0))) -> moyenne | W15: =_xlfn.XLOOKUP(VentesMagasins!$B15,Clients!ClientID,Région) -> Centre | X15: =INDEX(TypeClient,MATCH(VentesMagasins!$B15,Clients!ClientID)) -> Nouveau | Y15: févr
A16: 15 | B16: C1128 | C16: 45934 | D16: m2 | E16: Chaise | F16: Décoration | G16: 3 | H16: 350 | I16: 0.1 | J16: 945.0 | K16: 0 | L16: 5.0 | M16: =YEAR(VentesMagasins!$C16) -> 2025 | N16: {=MONTH(DateVente)} -> #VALUE! | O16: =PROPER(VentesMagasins!$F16) -> Décoration | P16: =VALUE(CLEAN(TRIM(SUBSTITUTE(VentesMagasins!$I16,".",",")))) -> 0.1 | Q16: =VALUE(TRIM(SUBSTITUTE(VentesMagasins!$J16,".",","))) -> 945 | R16: =Q16*(1-P16) -> 850.5 | S16: =IF(VentesMagasins!$K16=1,(-1)*R16,R16) -> 850.5 | T16: =IFERROR(VALUE(TRIM(SUBSTITUTE(VentesMagasins!$L16,".",","))),0) -> 5 | U16: =ROUND(IF(T16=0,AVERAGE(T16:T1015),T16),0) -> 5 | V16: =IF(AND(U16>0,U16<=2),"faible",IF(AND(U16>=3,U16<=4),"moyenne",IF(U16=5,"élévé",0))) -> élévé | W16: =_xlfn.XLOOKUP(VentesMagasins!$B16,Clients!ClientID,Région) -> Sud | X16: =INDEX(TypeClient,MATCH(VentesMagasins!$B16,Clients!ClientID)) -> Nouveau | Y16: oct
A17: 16 | B17: C1232 | C17: 45011 | D17: M2 | E17: Table | F17: Décoration | G17: 5 | H17: 146 | I17: 0.0 | J17: 730.0 | K17: 0 | L17: 4.0 | M17: =YEAR(VentesMagasins!$C17) -> 2023 | N17: {=MONTH(DateVente)} -> #VALUE! | O17: =PROPER(VentesMagasins!$F17) -> Décoration | P17: =VALUE(CLEAN(TRIM(SUBSTITUTE(VentesMagasins!$I17,".",",")))) -> 0 | Q17: =VALUE(TRIM(SUBSTITUTE(VentesMagasins!$J17,".",","))) -> 730 | R17: =Q17*(1-P17) -> 730 | S17: =IF(VentesMagasins!$K17=1,(-1)*R17,R17) -> 730 | T17: =IFERROR(VALUE(TRIM(SUBSTITUTE(VentesMagasins!$L17,".",","))),0) -> 4 | U17: =ROUND(IF(T17=0,AVERAGE(T17:T1016),T17),0) -> 4 | V17: =IF(AND(U17>0,U17<=2),"faible",IF(AND(U17>=3,U17<=4),"moyenne",IF(U17=5,"élévé",0))) -> moyenne | W17: =_xlfn.XLOOKUP(VentesMagasins!$B17,Clients!ClientID,Région) -> Nord | X17: =INDEX(TypeClient,MATCH(VentesMagasins!$B17,Clients!ClientID)) -> Fidèle | Y17: mars
A18: 17 | B18: C1104 | C18: 45669 | D18: M2 | E18: Tapis | F18: Meuble | G18: 5 | H18: 456 | I18: 0.1 | J18: 2052.0 | K18: 0 | L18: 5.0 | M18: =YEAR(VentesMagasins!$C18) -> 2025 | N18: {=MONTH(DateVente)} -> #VALUE! | O18: =PROPER(VentesMagasins!$F18) -> Meuble | P18: =VALUE(CLEAN(TRIM(SUBSTITUTE(VentesMagasins!$I18,".",",")))) -> 0.1 | Q18: =VALUE(TRIM(SUBSTITUTE(VentesMagasins!$J18,".",","))) -> 2052 | R18: =Q18*(1-P18) -> 1846.8 | S18: =IF(VentesMagasins!$K18=1,(-1)*R18,R18) -> 1846.8 | T18: =IFERROR(VALUE(TRIM(SUBSTITUTE(VentesMagasins!$L18,".",","))),0) -> 5 | U18: =ROUND(IF(T18=0,AVERAGE(T18:T1017),T18),0) -> 5 | V18: =IF(AND(U18>0,U18<=2),"faible",IF(AND(U18>=3,U18<=4),"moyenne",IF(U18=5,"élévé",0))) -> élévé | W18: =_xlfn.XLOOKUP(VentesMagasins!$B18,Clients!ClientID,Région) -> Centre | X18: =INDEX(TypeClient,MATCH(VentesMagasins!$B18,Clients!ClientID)) -> Fidèle | Y18: janv
A19: 18 | B19: C1183 | C19: 45669 | D19: M5 | E19: Canapé | F19: Électronique | G19: 4 | H19: 184 | I19: 0.15 | J19: 625.6 | K19: 0 | L19: 5.0 | M19: =YEAR(VentesMagasins!$C19) -> 2025 | N19: {=MONTH(DateVente)} -> #VALUE! | O19: =PROPER(VentesMagasins!$F19) -> Électronique | P19: =VALUE(CLEAN(TRIM(SUBSTITUTE(VentesMagasins!$I19,".",",")))) -> 0.15 | Q19: =VALUE(TRIM(SUBSTITUTE(VentesMagasins!$J19,".",","))) -> 625.6 | R19: =Q19*(1-P19) -> 531.76 | S19: =IF(VentesMagasins!$K19=1,(-1)*R19,R19) -> 531.76 | T19: =IFERROR(VALUE(TRIM(SUBSTITUTE(VentesMagasins!$L19,".",","))),0) -> 5 | U19: =ROUND(IF(T19=0,AVERAGE(T19:T1018),T19),0) -> 5 | V19: =IF(AND(U19>0,U19<=2),"faible",IF(AND(U19>=3,U19<=4),"moyenne",IF(U19=5,"élévé",0))) -> élévé | W19: =_xlfn.XLOOKUP(VentesMagasins!$B19,Clients!ClientID,Région) -> Centre | X19: =INDEX(TypeClient,MATCH(VentesMagasins!$B19,Clients!ClientID)) -> Fidèle | Y19: janv
A20: 19 | B20: C1182 | C20: 45299 | D20: M2 | E20: Enceinte | F20: Électronique | G20: 3 | H20: 141 | I20: 0.1 | J20: 380.7 | K20: 0 | L20: 4.0 | M20: =YEAR(VentesMagasins!$C20) -> 2024 | N20: {=MONTH(DateVente)} -> #VALUE! | O20: =PROPER(VentesMagasins!$F20) -> Électronique | P20: =VALUE(CLEAN(TRIM(SUBSTITUTE(VentesMagasins!$I20,".",",")))) -> 0.1 | Q20: =VALUE(TRIM(SUBSTITUTE(VentesMagasins!$J20,".",","))) -> 380.7 | R20: =Q20*(1-P20) -> 342.63 | S20: =IF(VentesMagasins!$K20=1,(-1)*R20,R20) -> 342.63 | T20: =IFERROR(VALUE(TRIM(SUBSTITUTE(VentesMagasins!$L20,".",","))),0) -> 4 | U20: =ROUND(IF(T20=0,AVERAGE(T20:T1019),T20),0) -> 4 | V20: =IF(AND(U20>0,U20<=2),"faible",IF(AND(U20>=3,U20<=4),"moyenne",IF(U20=5,"élévé",0))) -> moyenne | W20: =_xlfn.XLOOKUP(VentesMagasins!$B20,Clients!ClientID,Région) -> Sud | X20: =INDEX(TypeClient,MATCH(VentesMagasins!$B20,Clients!ClientID)) -> Occasionnel | Y20: janv
A21: 20 | B21: C1233 | C21: 45404 | D21: M3 | E21: Plante | F21: Meuble | G21: 3 | H21: 330 | I21: 0.15 | J21: 841.5 | K21: 0 | L21: 1.0 | M21: =YEAR(VentesMagasins!$C21) -> 2024 | N21: {=MONTH(DateVente)} -> #VALUE! | O21: =PROPER(VentesMagasins!$F21) -> Meuble | P21: =VALUE(CLEAN(TRIM(SUBSTITUTE(VentesMagasins!$I21,".",",")))) -> 0.15 | Q21: =VALUE(TRIM(SUBSTITUTE(VentesMagasins!$J21,".",","))) -> 841.5 | R21: =Q21*(1-P21) -> 715.275 | S21: =IF(VentesMagasins!$K21=1,(-1)*R21,R21) -> 715.275 | T21: =IFERROR(VALUE(TRIM(SUBSTITUTE(VentesMagasins!$L21,".",","))),0) -> 1 | U21: =ROUND(IF(T21=0,AVERAGE(T21:T1020),T21),0) -> 1 | V21: =IF(AND(U21>0,U21<=2),"faible",IF(AND(U21>=3,U21<=4),"moyenne",IF(U21=5,"élévé",0))) -> faible | W21: =_xlfn.XLOOKUP(VentesMagasins!$B21,Clients!ClientID,Région) -> Sud | X21: =INDEX(TypeClient,MATCH(VentesMagasins!$B21,Clients!ClientID)) -> Occasionnel | Y21: avr
A22: 21 | B22: C1290 | C22: 45318 | D22: M4 | E22: Enceinte | F22: Décoration | G22: 4 | H22: 443 | I22: 0.15 | J22: 1506.2 | K22: 0 | L22: 4.0 | M22: =YEAR(VentesMagasins!$C22) -> 2024 | N22: {=MONTH(DateVente)} -> #VALUE! | O22: =PROPER(VentesMagasins!$F22) -> Décoration | P22: =VALUE(CLEAN(TRIM(SUBSTITUTE(VentesMagasins!$I22,".",",")))) -> 0.15 | Q22: =VALUE(TRIM(SUBSTITUTE(VentesMagasins!$J22,".",","))) -> 1506.2 | R22: =Q22*(1-P22) -> 1280.27 | S22: =IF(VentesMagasins!$K22=1,(-1)*R22,R22) -> 1280.27 | T22: =IFERROR(VALUE(TRIM(SUBSTITUTE(VentesMagasins!$L22,".",","))),0) -> 4 | U22: =ROUND(IF(T22=0,AVERAGE(T22:T1021),T22),0) -> 4 | V22: =IF(AND(U22>0,U22<=2),"faible",IF(AND(U22>=3,U22<=4),"moyenne",IF(U22=5,"élévé",0))) -> moyenne | W22: =_xlfn.XLOOKUP(VentesMagasins!$B22,Clients!ClientID,Région) -> Nord | X22: =INDEX(TypeClient,MATCH(VentesMagasins!$B22,Clients!ClientID)) -> Fidèle | Y22: janv
A23: 22 | B23: C1214 | C23: 45877 | D23: M2 | E23: Table | F23: Électronique | G23: 3 | H23: 342 | I23: 0.05 | J23: 974.6999999999999 | K23: 1 | L23: 3.0 | M23: =YEAR(VentesMagasins!$C23) -> 2025 | N23: {=MONTH(DateVente)} -> #VALUE! | O23: =PROPER(VentesMagasins!$F23) -> Électronique | P23: =VALUE(CLEAN(TRIM(SUBSTITUTE(VentesMagasins!$I23,".",",")))) -> 0.05 | Q23: =VALUE(TRIM(SUBSTITUTE(VentesMagasins!$J23,".",","))) -> 974.7 | R23: =Q23*(1-P23) -> 925.965 | S23: =IF(VentesMagasins!$K23=1,(-1)*R23,R23) -> -925.965 | T23: =IFERROR(VALUE(TRIM(SUBSTITUTE(VentesMagasins!$L23,".",","))),0) -> 3 | U23: =ROUND(IF(T23=0,AVERAGE(T23:T1022),T23),0) -> 3 | V23: =IF(AND(U23>0,U23<=2),"faible",IF(AND(U23>=3,U23<=4),"moyenne",IF(U23=5,"élévé",0))) -> moyenne | W23: =_xlfn.XLOOKUP(VentesMagasins!$B23,Clients!ClientID,Région) -> Est | X23: =INDEX(TypeClient,MATCH(VentesMagasins!$B23,Clients!ClientID)) -> Fidèle | Y23: août
A24: 23 | B24: C1059 | C24: 45916 | D24: M3 | E24: Table | F24: Électronique | G24: 1 | H24: 55 | I24: 0.1 | J24: 49.5 | K24: 1 | L24: 4.0 | M24: =YEAR(VentesMagasins!$C24) -> 2025 | N24: {=MONTH(DateVente)} -> #VALUE! | O24: =PROPER(VentesMagasins!$F24) -> Électronique | P24: =VALUE(CLEAN(TRIM(SUBSTITUTE(VentesMagasins!$I24,".",",")))) -> 0.1 | Q24: =VALUE(TRIM(SUBSTITUTE(VentesMagasins!$J24,".",","))) -> 49.5 | R24: =Q24*(1-P24) -> 44.55 | S24: =IF(VentesMagasins!$K24=1,(-1)*R24,R24) -> -44.55 | T24: =IFERROR(VALUE(TRIM(SUBSTITUTE(VentesMagasins!$L24,".",","))),0) -> 4 | U24: =ROUND(IF(T24=0,AVERAGE(T24:T1023),T24),0) -> 4 | V24: =IF(AND(U24>0,U24<=2),"faible",IF(AND(U24>=3,U24<=4),"moyenne",IF(U24=5,"élévé",0))) -> moyenne | W24: =_xlfn.XLOOKUP(VentesMagasins!$B24,Clients!ClientID,Région) -> Ouest | X24: =INDEX(TypeClient,MATCH(VentesMagasins!$B24,Clients!ClientID)) -> Nouveau | Y24: sept
A25: 24 | B25: C1140 | C25: 45352 | D25: M2 | E25: Chaise | F25: Décoration | G25: 5 | H25: 102 | I25: 0.0 | J25: 510.0 | K25: 1 | L25: 1.0 | M25: =YEAR(VentesMagasins!$C25) -> 2024 | N25: {=MONTH(DateVente)} -> #VALUE! | O25: =PROPER(VentesMagasins!$F25) -> Décoration | P25: =VALUE(CLEAN(TRIM(SUBSTITUTE(VentesMagasins!$I25,".",",")))) -> 0 | Q25: =VALUE(TRIM(SUBSTITUTE(VentesMagasins!$J25,".",","))) -> 510 | R25: =Q25*(1-P25) -> 510 | S25: =IF(VentesMagasins!$K25=1,(-1)*R25,R25) -> -510 | T25: =IFERROR(VALUE(TRIM(SUBSTITUTE(VentesMagasins!$L25,".",","))),0) -> 1 | U25: =ROUND(IF(T25=0,AVERAGE(T25:T1024),T25),0) -> 1 | V25: =IF(AND(U25>0,U25<=2),"faible",IF(AND(U25>=3,U25<=4),"moyenne",IF(U25=5,"élévé",0))) -> faible | W25: =_xlfn.XLOOKUP(VentesMagasins!$B25,Clients!ClientID,Région) -> Centre | X25: =INDEX(TypeClient,MATCH(VentesMagasins!$B25,Clients!ClientID)) -> Nouveau | Y25: mars
A26: 25 | B26: C1285 | C26: 45229 | D26: M5 | E26: Canapé | F26: Décoration | G26: 5 | H26: 298 | I26: 0.15 | J26: 1266.5 | K26: 0 | L26: 5.0 | M26: =YEAR(VentesMagasins!$C26) -> 2023 | N26: {=MONTH(DateVente)} -> #VALUE! | O26: =PROPER(VentesMagasins!$F26) -> Décoration | P26: =VALUE(CLEAN(TRIM(SUBSTITUTE(VentesMagasins!$I26,".",",")))) -> 0.15 | Q26: =VALUE(TRIM(SUBSTITUTE(VentesMagasins!$J26,".",","))) -> 1266.5 | R26: =Q26*(1-P26) -> 1076.525 | S26: =IF(VentesMagasins!$K26=1,(-1)*R26,R26) -> 1076.525 | T26: =IFERROR(VALUE(TRIM(SUBSTITUTE(VentesMagasins!$L26,".",","))),0) -> 5 | U26: =ROUND(IF(T26=0,AVERAGE(T26:T1025),T26),0) -> 5 | V26: =IF(AND(U26>0,U26<=2),"faible",IF(AND(U26>=3,U26<=4),"moyenne",IF(U26=5,"élévé",0))) -> élévé | W26: =_xlfn.XLOOKUP(VentesMagasins!$B26,Clients!ClientID,Région) -> Ouest | X26: =INDEX(TypeClient,MATCH(VentesMagasins!$B26,Clients!ClientID)) -> Fidèle | Y26: oct
A27: 26 | B27: C1182 | C27: 45235 | D27: M5 | E27: Plante | F27: Meuble | G27: 1 | H27: 207 | I27: 0.1 | J27: 186.3 | K27: 0 | L27: 4.0 | M27: =YEAR(VentesMagasins!$C27) -> 2023 | N27: {=MONTH(DateVente)} -> #VALUE! | O27: =PROPER(VentesMagasins!$F27) -> Meuble | P27: =VALUE(CLEAN(TRIM(SUBSTITUTE(VentesMagasins!$I27,".",",")))) -> 0.1 | Q27: =VALUE(TRIM(SUBSTITUTE(VentesMagasins!$J27,".",","))) -> 186.3 | R27: =Q27*(1-P27) -> 167.67 | S27: =IF(VentesMagasins!$K27=1,(-1)*R27,R27) -> 167.67 | T27: =IFERROR(VALUE(TRIM(SUBSTITUTE(VentesMagasins!$L27,".",","))),0) -> 4 | U27: =ROUND(IF(T27=0,AVERAGE(T27:T1026),T27),0) -> 4 | V27: =IF(AND(U27>0,U27<=2),"faible",IF(AND(U27>=3,U27<=4),"moyenne",IF(U27=5,"élévé",0))) -> moyenne | W27: =_xlfn.XLOOKUP(VentesMagasins!$B27,Clients!ClientID,Région) -> Sud | X27: =INDEX(TypeClient,MATCH(VentesMagasins!$B27,Clients!ClientID)) -> Occasionnel | Y27: nov
A28: 27 | B28: C1106 | C28: 45920 | D28: M3 | E28: Télévision | F28: Décoration | G28: 5 | H28: 211 | I28: 0.15 | J28: 896.75 | K28: 1 | M28: =YEAR(VentesMagasins!$C28) -> 2025 | N28: {=MONTH(DateVente)} -> #VALUE! | O28: =PROPER(VentesMagasins!$F28) -> Décoration | P28: =VALUE(CLEAN(TRIM(SUBSTITUTE(VentesMagasins!$I28,".",",")))) -> 0.15 | Q28: =VALUE(TRIM(SUBSTITUTE(VentesMagasins!$J28,".",","))) -> 896.75 | R28: =Q28*(1-P28) -> 762.2375 | S28: =IF(VentesMagasins!$K28=1,(-1)*R28,R28) -> -762.2375 | T28: =IFERROR(VALUE(TRIM(SUBSTITUTE(VentesMagasins!$L28,".",","))),0) -> 0 | U28: =ROUND(IF(T28=0,AVERAGE(T28:T1027),T28),0) -> 2 | V28: =IF(AND(U28>0,U28<=2),"faible",IF(AND(U28>=3,U28<=4),"moyenne",IF(U28=5,"élévé",0))) -> faible | W28: =_xlfn.XLOOKUP(VentesMagasins!$B28,Clients!ClientID,Région) -> Nord | X28: =INDEX(TypeClient,MATCH(VentesMagasins!$B28,Clients!ClientID)) -> Nouveau | Y28: sept
A29: 28 | B29: C1282 | C29: 45867 | D29: M3 | E29: Table | F29: Électronique | G29: 4 | H29: 103 | I29: 0.0 | J29: 412.0 | K29: 0 | L29: 5.0 | M29: =YEAR(VentesMagasins!$C29) -> 2025 | N29: {=MONTH(DateVente)} -> #VALUE! | O29: =PROPER(VentesMagasins!$F29) -> Électronique | P29: =VALUE(CLEAN(TRIM(SUBSTITUTE(VentesMagasins!$I29,".",",")))) -> 0 | Q29: =VALUE(TRIM(SUBSTITUTE(VentesMagasins!$J29,".",","))) -> 412 | R29: =Q29*(1-P29) -> 412 | S29: =IF(VentesMagasins!$K29=1,(-1)*R29,R29) -> 412 | T29: =IFERROR(VALUE(TRIM(SUBSTITUTE(VentesMagasins!$L29,".",","))),0) -> 5 | U29: =ROUND(IF(T29=0,AVERAGE(T29:T1028),T29),0) -> 5 | V29: =IF(AND(U29>0,U29<=2),"faible",IF(AND(U29>=3,U29<=4),"moyenne",IF(U29=5,"élévé",0))) -> élévé | W29: =_xlfn.XLOOKUP(VentesMagasins!$B29,Clients!ClientID,Région) -> Sud | X29: =INDEX(TypeClient,MATCH(VentesMagasins!$B29,Clients!ClientID)) -> Fidèle | Y29: juil
A30: 29 | B30: C1094 | C30: 45547 | D30: M3 | E30: Télévision | F30: Électronique | G30: 5 | H30: 428 | I30: 0.1 | J30: 1926.0 | K30: 0 | L30: 2.0 | M30: =YEAR(VentesMagasins!$C30) -> 2024 | N30: {=MONTH(DateVente)} -> #VALUE! | O30: =PROPER(VentesMagasins!$F30) -> Électronique | P30: =VALUE(CLEAN(TRIM(SUBSTITUTE(VentesMagasins!$I30,".",",")))) -> 0.1 | Q30: =VALUE(TRIM(SUBSTITUTE(VentesMagasins!$J30,".",","))) -> 1926 | R30: =Q30*(1-P30) -> 1733.4 | S30: =IF(VentesMagasins!$K30=1,(-1)*R30,R30) -> 1733.4 | T30: =IFERROR(VALUE(TRIM(SUBSTITUTE(VentesMagasins!$L30,".",","))),0) -> 2 | U30: =ROUND(IF(T30=0,AVERAGE(T30:T1029),T30),0) -> 2 | V30: =IF(AND(U30>0,U30<=2),"faible",IF(AND(U30>=3,U30<=4),"moyenne",IF(U30=5,"élévé",0))) -> faible | W30: =_xlfn.XLOOKUP(VentesMagasins!$B30,Clients!ClientID,Région) -> Centre | X30: =INDEX(TypeClient,MATCH(VentesMagasins!$B30,Clients!ClientID)) -> Nouveau | Y30: sept
A31: 30 | B31: C1141 | C31: 45536 | D31: M3 | E31: Tapis | F31: Décoration | G31: 3 | H31: 123 | I31: 0.15 | J31: 313.65 | K31: 0 | L31: 2.0 | M31: =YEAR(VentesMagasins!$C31) -> 2024 | N31: {=MONTH(DateVente)} -> #VALUE! | O31: =PROPER(VentesMagasins!$F31) -> Décoration | P31: =VALUE(CLEAN(TRIM(SUBSTITUTE(VentesMagasins!$I31,".",",")))) -> 0.15 | Q31: =VALUE(TRIM(SUBSTITUTE(VentesMagasins!$J31,".",","))) -> 313.65 | R31: =Q31*(1-P31) -> 266.6025 | S31: =IF(VentesMagasins!$K31=1,(-1)*R31,R31) -> 266.6025 | T31: =IFERROR(VALUE(TRIM(SUBSTITUTE(VentesMagasins!$L31,".",","))),0) -> 2 | U31: =ROUND(IF(T31=0,AVERAGE(T31:T1030),T31),0) -> 2 | V31: =IF(AND(U31>0,U31<=2),"faible",IF(AND(U31>=3,U31<=4),"moyenne",IF(U31=5,"élévé",0))) -> faible | W31: =_xlfn.XLOOKUP(VentesMagasins!$B31,Clients!ClientID,Région) -> Est | X31: =INDEX(TypeClient,MATCH(VentesMagasins!$B31,Clients!ClientID)) -> Fidèle | Y31: sept
A32: 31 | B32: C1295 | C32: 44944 | D32: M1 | E32: Chaise | F32: Décoration | G32: 2 | H32: 151 | I32: 0.1 | J32: 271.8 | K32: 0 | L32: 1.0 | M32: =YEAR(VentesMagasins!$C32) -> 2023 | N32: {=MONTH(DateVente)} -> #VALUE! | O32: =PROPER(VentesMagasins!$F32) -> Décoration | P32: =VALUE(CLEAN(TRIM(SUBSTITUTE(VentesMagasins!$I32,".",",")))) -> 0.1 | Q32: =VALUE(TRIM(SUBSTITUTE(VentesMagasins!$J32,".",","))) -> 271.8 | R32: =Q32*(1-P32) -> 244.62 | S32: =IF(VentesMagasins!$K32=1,(-1)*R32,R32) -> 244.62 | T32: =IFERROR(VALUE(TRIM(SUBSTITUTE(VentesMagasins!$L32,".",","))),0) -> 1 | U32: =ROUND(IF(T32=0,AVERAGE(T32:T1031),T32),0) -> 1 | V32: =IF(AND(U32>0,U32<=2),"faible",IF(AND(U32>=3,U32<=4),"moyenne",IF(U32=5,"élévé",0))) -> faible | W32: =_xlfn.XLOOKUP(VentesMagasins!$B32,Clients!ClientID,Région) -> Sud | X32: =INDEX(TypeClient,MATCH(VentesMagasins!$B32,Clients!ClientID)) -> Nouveau | Y32: janv
A33: 32 | B33: C1095 | C33: 44990 | D33: M2 | E33: Chaise | F33: Électronique | G33: 5 | H33: 36 | I33: 0.0 | J33: 162.0 | K33: 0 | M33: =YEAR(VentesMagasins!$C33) -> 2023 | N33: {=MONTH(DateVente)} -> #VALUE! | O33: =PROPER(VentesMagasins!$F33) -> Électronique | P33: =VALUE(CLEAN(TRIM(SUBSTITUTE(VentesMagasins!$I33,".",",")))) -> 0 | Q33: =VALUE(TRIM(SUBSTITUTE(VentesMagasins!$J33,".",","))) -> 162 | R33: =Q33*(1-P33) -> 162 | S33: =IF(VentesMagasins!$K33=1,(-1)*R33,R33) -> 162 | T33: =IFERROR(VALUE(TRIM(SUBSTITUTE(VentesMagasins!$L33,".",","))),0) -> 0 | U33: =ROUND(IF(T33=0,AVERAGE(T33:T1032),T33),0) -> 2 | V33: =IF(AND(U33>0,U33<=2),"faible",IF(AND(U33>=3,U33<=4),"moyenne",IF(U33=5,"élévé",0))) -> faible | W33: =_xlfn.XLOOKUP(VentesMagasins!$B33,Clients!ClientID,Région) -> Est | X33: =INDEX(TypeClient,MATCH(VentesMagasins!$B33,Clients!ClientID)) -> Fidèle | Y33: mars
A34: 33 | B34: C1047 | C34: 45872 | D34: M4 | E34: Télévision | F34: Meuble | G34: 5 | H34: 478 | I34: 0.0 | J34: 2390.0 | K34: 0 | M34: =YEAR(VentesMagasins!$C34) -> 2025 | N34: {=MONTH(DateVente)} -> #VALUE! | O34: =PROPER(VentesMagasins!$F34) -> Meuble | P34: =VALUE(CLEAN(TRIM(SUBSTITUTE(VentesMagasins!$I34,".",",")))) -> 0 | Q34: =VALUE(TRIM(SUBSTITUTE(VentesMagasins!$J34,".",","))) -> 2390 | R34: =Q34*(1-P34) -> 2390 | S34: =IF(VentesMagasins!$K34=1,(-1)*R34,R34) -> 2390 | T34: =IFERROR(VALUE(TRIM(SUBSTITUTE(VentesMagasins!$L34,".",","))),0) -> 0 | U34: =ROUND(IF(T34=0,AVERAGE(T34:T1033),T34),0) -> 2 | V34: =IF(AND(U34>0,U34<=2),"faible",IF(AND(U34>=3,U34<=4),"moyenne",IF(U34=5,"élévé",0))) -> faible | W34: =_xlfn.XLOOKUP(VentesMagasins!$B34,Clients!ClientID,Région) -> Est | X34: =INDEX(TypeClient,MATCH(VentesMagasins!$B34,Clients!ClientID)) -> Occasionnel | Y34: août
A35: 34 | B35: C1215 | C35: 45164 | D35: M2 | E35: Plante | F35: Décoration | G35: 2 | H35: 354 | I35: 0.15 | J35: 541.62 | K35: 0 | L35: 1.0 | M35: =YEAR(VentesMagasins!$C35) -> 2023 | N35: {=MONTH(DateVente)} -> #VALUE! | O35: =PROPER(VentesMagasins!$F35) -> Décoration | P35: =VALUE(CLEAN(TRIM(SUBSTITUTE(VentesMagasins!$I35,".",",")))) -> 0.15 | Q35: =VALUE(TRIM(SUBSTITUTE(VentesMagasins!$J35,".",","))) -> 541.62 | R35: =Q35*(1-P35) -> 460.377 | S35: =IF(VentesMagasins!$K35=1,(-1)*R35,R35) -> 460.377 | T35: =IFERROR(VALUE(TRIM(SUBSTITUTE(VentesMagasins!$L35,".",","))),0) -> 1 | U35: =ROUND(IF(T35=0,AVERAGE(T35:T1034),T35),0) -> 1 | V35: =IF(AND(U35>0,U35<=2),"faible",IF(AND(U35>=3,U35<=4),"moyenne",IF(U35=5,"élévé",0))) -> faible | W35: =_xlfn.XLOOKUP(VentesMagasins!$B35,Clients!ClientID,Région) -> Est | X35: =INDEX(TypeClient,MATCH(VentesMagasins!$B35,Clients!ClientID)) -> Occasionnel | Y35: août
A36: 35 | B36: C1058 | C36: 45091 | D36: M5 | E36: Plante | F36: Électronique | G36: 2 | H36: 270 | I36: 0.05 | J36: 513.0 | K36: 1 | L36: 1.0 | M36: =YEAR(VentesMagasins!$C36) -> 2023 | N36: {=MONTH(DateVente)} -> #VALUE! | O36: =PROPER(VentesMagasins!$F36) -> Électronique | P36: =VALUE(CLEAN(TRIM(SUBSTITUTE(VentesMagasins!$I36,".",",")))) -> 0.05 | Q36: =VALUE(TRIM(SUBSTITUTE(VentesMagasins!$J36,".",","))) -> 513 | R36: =Q36*(1-P36) -> 487.35 | S36: =IF(VentesMagasins!$K36=1,(-1)*R36,R36) -> -487.35 | T36: =IFERROR(VALUE(TRIM(SUBSTITUTE(VentesMagasins!$L36,".",","))),0) -> 1 | U36: =ROUND(IF(T36=0,AVERAGE(T36:T1035),T36),0) -> 1 | V36: =IF(AND(U36>0,U36<=2),"faible",IF(AND(U36>=3,U36<=4),"moyenne",IF(U36=5,"élévé",0))) -> faible | W36: =_xlfn.XLOOKUP(VentesMagasins!$B36,Clients!ClientID,Région) -> Centre | X36: =INDEX(TypeClient,MATCH(VentesMagasins!$B36,Clients!ClientID)) -> Nouveau | Y36: juin
A37: 36 | B37: C1256 | C37: 45571 | D37: M3 | E37: Chaise | F37: Décoration | G37: 5 | H37: 199 | I37: 0.1 | J37: 895.5 | K37: 0 | L37: 5.0 | M37: =YEAR(VentesMagasins!$C37) -> 2024 | N37: {=MONTH(DateVente)} -> #VALUE! | O37: =PROPER(VentesMagasins!$F37) -> Décoration | P37: =VALUE(CLEAN(TRIM(SUBSTITUTE(VentesMagasins!$I37,".",",")))) -> 0.1 | Q37: =VALUE(TRIM(SUBSTITUTE(VentesMagasins!$J37,".",","))) -> 895.5 | R37: =Q37*(1-P37) -> 805.95 | S37: =IF(VentesMagasins!$K37=1,(-1)*R37,R37) -> 805.95 | T37: =IFERROR(VALUE(TRIM(SUBSTITUTE(VentesMagasins!$L37,".",","))),0) -> 5 | U37: =ROUND(IF(T37=0,AVERAGE(T37:T1036),T37),0) -> 5 | V37: =IF(AND(U37>0,U37<=2),"faible",IF(AND(U37>=3,U37<=4),"moyenne",IF(U37=5,"élévé",0))) -> élévé | W37: =_xlfn.XLOOKUP(VentesMagasins!$B37,Clients!ClientID,Région) -> Est | X37: =INDEX(TypeClient,MATCH(VentesMagasins!$B37,Clients!ClientID)) -> Nouveau | Y37: oct
A38: 37 | B38: C1012 | C38: 45679 | D38: M1 | E38: Plante | F38: Décoration | G38: 1 | H38: 329 | I38: 0.05 | J38: 312.55 | K38: 0 | M38: =YEAR(VentesMagasins!$C38) -> 2025 | N38: {=MONTH(DateVente)} -> #VALUE! | O38: =PROPER(VentesMagasins!$F38) -> Décoration | P38: =VALUE(CLEAN(TRIM(SUBSTITUTE(VentesMagasins!$I38,".",",")))) -> 0.05 | Q38: =VALUE(TRIM(SUBSTITUTE(VentesMagasins!$J38,".",","))) -> 312.55 | R38: =Q38*(1-P38) -> 296.9225 | S38: =IF(VentesMagasins!$K38=1,(-1)*R38,R38) -> 296.9225 | T38: =IFERROR(VALUE(TRIM(SUBSTITUTE(VentesMagasins!$L38,".",","))),0) -> 0 | U38: =ROUND(IF(T38=0,AVERAGE(T38:T1037),T38),0) -> 3 | V38: =IF(AND(U38>0,U38<=2),"faible",IF(AND(U38>=3,U38<=4),"moyenne",IF(U38=5,"élévé",0))) -> moyenne | W38: =_xlfn.XLOOKUP(VentesMagasins!$B38,Clients!ClientID,Région) -> Ouest | X38: =INDEX(TypeClient,MATCH(VentesMagasins!$B38,Clients!ClientID)) -> Nouveau | Y38: janv
A39: 38 | B39: C1207 | C39: 45165 | D39: M3 | E39: Canapé | F39: Décoration | G39: 4 | H39: 311 | I39: 0.05 | J39: 1181.8 | K39: 0 | L39: 5.0 | M39: =YEAR(VentesMagasins!$C39) -> 2023 | N39: {=MONTH(DateVente)} -> #VALUE! | O39: =PROPER(VentesMagasins!$F39) -> Décoration | P39: =VALUE(CLEAN(TRIM(SUBSTITUTE(VentesMagasins!$I39,".",",")))) -> 0.05 | Q39: =VALUE(TRIM(SUBSTITUTE(VentesMagasins!$J39,".",","))) -> 1181.8 | R39: =Q39*(1-P39) -> 1122.71 | S39: =IF(VentesMagasins!$K39=1,(-1)*R39,R39) -> 1122.71 | T39: =IFERROR(VALUE(TRIM(SUBSTITUTE(VentesMagasins!$L39,".",","))),0) -> 5 | U39: =ROUND(IF(T39=0,AVERAGE(T39:T1038),T39),0) -> 5 | V39: =IF(AND(U39>0,U39<=2),"faible",IF(AND(U39>=3,U39<=4),"moyenne",IF(U39=5,"élévé",0))) -> élévé | W39: =_xlfn.XLOOKUP(VentesMagasins!$B39,Clients!ClientID,Région) -> Est | X39: =INDEX(TypeClient,MATCH(VentesMagasins!$B39,Clients!ClientID)) -> Fidèle | Y39: août
A40: 39 | B40: C1089 | C40: 46003 | D40: M1 | E40: Plante | F40: Décoration | G40: 3 | H40: 46 | I40: 0.05 | J40: 131.1 | K40: 0 | L40: 3.0 | M40: =YEAR(VentesMagasins!$C40) -> 2025 | N40: {=MONTH(DateVente)} -> #VALUE! | O40: =PROPER(VentesMagasins!$F40) -> Décoration | P40: =VALUE(CLEAN(TRIM(SUBSTITUTE(VentesMagasins!$I40,".",",")))) -> 0.05 | Q40: =VALUE(TRIM(SUBSTITUTE(VentesMagasins!$J40,".",","))) -> 131.1 | R40: =Q40*(1-P40) -> 124.545 | S40: =IF(VentesMagasins!$K40=1,(-1)*R40,R40) -> 124.545 | T40: =IFERROR(VALUE(TRIM(SUBSTITUTE(VentesMagasins!$L40,".",","))),0) -> 3 | U40: =ROUND(IF(T40=0,AVERAGE(T40:T1039),T40),0) -> 3 | V40: =IF(AND(U40>0,U40<=2),"faible",IF(AND(U40>=3,U40<=4),"moyenne",IF(U40=5,"élévé",0))) -> moyenne | W40: =_xlfn.XLOOKUP(VentesMagasins!$B40,Clients!ClientID,Région) -> Centre | X40: =INDEX(TypeClient,MATCH(VentesMagasins!$B40,Clients!ClientID)) -> Occasionnel | Y40: déc
...

Sheet Clients
A1: ClientID1 | B1: Région | C1: TypeClient
A2: C1000 | B2: Centre | C2: Occasionnel
A3: C1001 | B3: Ouest | C3: Nouveau
A4: C1002 | B4: Nord | C4: Occasionnel
A5: C1003 | B5: Centre | C5: Fidèle
A6: C1004 | B6: Sud | C6: Fidèle
A7: C1005 | B7: Ouest | C7: Occasionnel
A8: C1006 | B8: Sud | C8: Nouveau
A9: C1007 | B9: Centre | C9: Occasionnel
A10: C1008 | B10: Nord | C10: Fidèle
A11: C1009 | B11: Ouest | C11: Occasionnel
A12: C1010 | B12: Centre | C12: Nouveau
... A301: C1299 | B301: Est | C301: Occasionnel

Sheet Feuil1
